package def

import (
	"errors"
	"fmt"
)

func DeferCall() {
	defer func() { fmt.Println("打印前") }()
	defer func() { fmt.Println("打印中") }()
	defer func() { fmt.Println("打印后") }()

	panic("触发异常")
}

func DeferCallV2() {
	fmt.Println(doubleScore(0))    //0
	fmt.Println(doubleScore(20.0)) //40
	fmt.Println(doubleScore(50.0)) //50
	fmt.Println(getErr())
}

/*函数的return value 不是原子操作.而是在编译器中分解为两部分：返回值赋值 和 return 。而defer刚好被插入到末尾的return前执行*/
func doubleScore(source float32) (score float32) {
	defer func() {
		if score < 1 || score >= 100 {
			score = source
		}
	}()
	return source * 2
}

func DeferCallV3() {
	a := 1
	b := 2
	defer calc("1", a, calc("10", a, b))
	a = 0
	defer calc("2", a, calc("20", a, b))
	b = 1
}

func calc(index string, a, b int) int {
	ret := a + b
	fmt.Println(index, a, b, ret)
	return ret
}

func getErr() error {
	var err error
	defer func() {
		err = errors.New("defered err")
	}()
	return errors.New("this is an err")
}
